Workbook

Sheet Vendor_H
A1: Series | B1: CardType | C1: CardCode | D1: AliasName | E1: U_SLD_Title | F1: U_SLD_FullName | G1: CardName | H1: FederalTaxID | I1: GroupCode | J1: PayTermsGrpCode | K1: Currency | L1: VatGroup | M1: DownPaymentClearAct | N1: DebitorAccount | O1: Phone1 | P1: Phone2 | Q1: Fax | R1: GlobalLocationNumber
A2: Series | B2: CardType | C2: CardCode | D2: AliasName | E2: U_SLD_Title | F2: U_SLD_FullName | G2: CardName | H2: LicTradNum | I2: GroupCode | J2: GroupNum | K2: Currency | L2: ECVatGroup | M2: DpmClear | N2: DebPayAcct | O2: Phone1 | P2: Phone2 | Q2: Fax | R2: GlblLocNum
A3: =_xlfn.XLOOKUP(I3,Sheet1!B:B,Sheet1!A:A,0) -> 942 | B3: S | C3: 1 | D3: ก-0001 | F3: กองทุนรวมสิทธิการเช่าอสังหาริมทรัพย์ฟิวเจอร์พาร์ค | G3: กองทุนรวมสิทธิการเช่าอสังหาริมทรัพย์ฟิวเจอร์พาร์ค | H3: 994000628251 | I3: 109 | K3: THB | L3: IG07 | M3: _SYS00000000092 | N3: _SYS00000000146 | O3: 02-9580011 | Q3: 02-9580081 | R3: 0
A4: =_xlfn.XLOOKUP(I4,Sheet1!B:B,Sheet1!A:A,0) -> 939 | B4: S | C4: 2 | D4: ก-0002 | E4: บริษัท | F4: เกรท เฟรนด์ จำกัด | G4: บริษัท เกรท เฟรนด์ จำกัด | H4: 105561206957 | I4: 101 | K4: THB | L4: IG07 | M4: _SYS00000000092 | N4: _SYS00000000146 | R4: 0
A5: =_xlfn.XLOOKUP(I5,Sheet1!B:B,Sheet1!A:A,0) -> 940 | B5: S | C5: 3 | D5: ก-0003 | E5: นางสาว | F5: กันธิชา ชีพสมุทร | G5: นางสาว กันธิชา ชีพสมุทร | H5: 1229900559157 | I5: 107 | K5: THB | L5: IG07 | M5: _SYS00000000092 | N5: _SYS00000000146
A6: =_xlfn.XLOOKUP(I6,Sheet1!B:B,Sheet1!A:A,0) -> 939 | B6: S | C6: 4 | D6: ก-0004 | E6: บริษัท | F6: กูธ จำกัด | G6: บริษัท กูธ จำกัด | H6: 105549021438 | I6: 101 | K6: THB | L6: IG07 | M6: _SYS00000000092 | N6: _SYS00000000146 | O6: 02-1850908 | R6: 0
A7: =_xlfn.XLOOKUP(I7,Sheet1!B:B,Sheet1!A:A,0) -> 939 | B7: S | C7: 5 | D7: ก-0005 | E7: บริษัท | F7: กัชคลาวด์(ประเทศไทย)จำกัด | G7: บริษัท กัชคลาวด์(ประเทศไทย)จำกัด | H7: 105559067686 | I7: 101 | K7: THB | L7: IG07 | M7: _SYS00000000092 | N7: _SYS00000000146 | O7: 085-840-4940 | R7: 0
A8: =_xlfn.XLOOKUP(I8,Sheet1!B:B,Sheet1!A:A,0) -> 940 | B8: S | C8: 6 | D8: ก-0006 | E8: นางสาว | F8: กมเลศ ฤทธิ์เดชา | G8: นางสาว กมเลศ ฤทธิ์เดชา | H8: 1101800485864 | I8: 107 | K8: THB | L8: IG07 | M8: _SYS00000000092 | N8: _SYS00000000146
A9: =_xlfn.XLOOKUP(I9,Sheet1!B:B,Sheet1!A:A,0) -> 939 | B9: S | C9: 7 | D9: ก-0007 | E9: บริษัท | F9: กูรูเช็ค จำกัด | G9: บริษัท กูรูเช็ค จำกัด | H9: 105560136696 | I9: 101 | K9: THB | L9: IG07 | M9: _SYS00000000092 | N9: _SYS00000000146 | R9: 0
A10: =_xlfn.XLOOKUP(I10,Sheet1!B:B,Sheet1!A:A,0) -> 939 | B10: S | C10: 8 | D10: ก-0008 | E10: บริษัท | F10: กาไชย จำกัด | G10: บริษัท กาไชย จำกัด | H10: 105556155304 | I10: 101 | K10: THB | L10: IG07 | M10: _SYS00000000092 | N10: _SYS00000000146 | R10: 0
A11: =_xlfn.XLOOKUP(I11,Sheet1!B:B,Sheet1!A:A,0) -> 939 | B11: S | C11: 9 | D11: ก-0009 | E11: บริษัท | F11: กิฟต์แมนูแฟคตอรี่ จำกัด | G11: บริษัท กิฟต์แมนูแฟคตอรี่ จำกัด | H11: 105561131337 | I11: 101 | K11: THB | L11: IG07 | M11: _SYS00000000092 | N11: _SYS00000000146 | R11: 0
A12: =_xlfn.XLOOKUP(I12,Sheet1!B:B,Sheet1!A:A,0) -> 939 | B12: S | C12: 10 | D12: ก-0010 | E12: บริษัท | F12: ก้าวกระโดด เอ็นเตอร์เทนเมนท์ จำกัด | G12: บริษัท ก้าวกระโดด เอ็นเตอร์เทนเมนท์ จำกัด | H12: 105560054924 | I12: 101 | K12: THB | L12: IG07 | M12: _SYS00000000092 | N12: _SYS00000000146 | R12: 0
A13: =_xlfn.XLOOKUP(I13,Sheet1!B:B,Sheet1!A:A,0) -> 939 | B13: S | C13: 11 | D13: ก-0011 | E13: บริษัท | F13: กรุงเทพประกันภัย จำกัด (มหาชน) | G13: บริษัท กรุงเทพประกันภัย จำกัด (มหาชน) | H13: 107536000625 | I13: 101 | K13: THB | L13: IG07 | M13: _SYS00000000092 | N13: _SYS00000000146 | R13: 0
A14: =_xlfn.XLOOKUP(I14,Sheet1!B:B,Sheet1!A:A,0) -> 940 | B14: S | C14: 12 | D14: ก-0012 | E14: นางสาว | F14: กมลรัตน์ เรืองยศ | G14: นางสาว กมลรัตน์ เรืองยศ | H14: 1100702444801 | I14: 107 | K14: THB | L14: IG07 | M14: _SYS00000000092 | N14: _SYS00000000146
A15: =_xlfn.XLOOKUP(I15,Sheet1!B:B,Sheet1!A:A,0) -> 939 | B15: S | C15: 13 | D15: ก-0013 | E15: บริษัท | F15: กันติชา โปรดักชั่นส์ จำกัด | G15: บริษัท กันติชา โปรดักชั่นส์ จำกัด | H15: 105563136841 | I15: 101 | K15: THB | L15: IG07 | M15: _SYS00000000092 | N15: _SYS00000000146 | R15: 0
A16: =_xlfn.XLOOKUP(I16,Sheet1!B:B,Sheet1!A:A,0) -> 939 | B16: S | C16: 14 | D16: ก-0014 | E16: บริษัท | F16: ธนาคารกรุงไทย จำกัด (มหาชน) | G16: บริษัท ธนาคารกรุงไทย จำกัด (มหาชน) | H16: 107537000882 | I16: 101 | K16: THB | L16: IG07 | M16: _SYS00000000092 | N16: _SYS00000000146 | R16: 0
A17: =_xlfn.XLOOKUP(I17,Sheet1!B:B,Sheet1!A:A,0) -> 940 | B17: S | C17: 15 | D17: ก-0015 | E17: นางสาว | F17: กาญจนาพร ศรีสวัสดิ์ | G17: นางสาว กาญจนาพร ศรีสวัสดิ์ | H17: 1103702207306 | I17: 107 | K17: THB | L17: IG07 | M17: _SYS00000000092 | N17: _SYS00000000146
A18: =_xlfn.XLOOKUP(I18,Sheet1!B:B,Sheet1!A:A,0) -> 939 | B18: S | C18: 16 | D18: ก-0016 | E18: บริษัท | F18: กลุ๊กส์คินด์ จำกัด | G18: บริษัท กลุ๊กส์คินด์ จำกัด | H18: 205564033173 | I18: 101 | K18: THB | L18: IG07 | M18: _SYS00000000092 | N18: _SYS00000000146 | R18: 0
A19: =_xlfn.XLOOKUP(I19,Sheet1!B:B,Sheet1!A:A,0) -> 985 | B19: S | C19: 17 | D19: ก-0017 | E19: ห้างหุ้นส่วนจำกัด | F19: กราฟฟิกโซน | G19: ห้างหุ้นส่วนจำกัด กราฟฟิกโซน | H19: 403557001179 | I19: 108 | K19: THB | L19: IG07 | M19: _SYS00000000092 | N19: _SYS00000000146 | R19: 0
A20: =_xlfn.XLOOKUP(I20,Sheet1!B:B,Sheet1!A:A,0) -> 939 | B20: S | C20: 18 | D20: ก-0018 | E20: บริษัท | F20: เก๋ไก๋ สไลเดอร์ จำกัด | G20: บริษัท เก๋ไก๋ สไลเดอร์ จำกัด | H20: 135564014625 | I20: 101 | K20: THB | L20: IG07 | M20: _SYS00000000092 | N20: _SYS00000000146 | R20: 0
A21: =_xlfn.XLOOKUP(I21,Sheet1!B:B,Sheet1!A:A,0) -> 940 | B21: S | C21: 19 | D21: ก-0019 | E21: นาย | F21: กันตพงศ์ พรมพิทักษ์ | G21: นาย กันตพงศ์ พรมพิทักษ์ | H21: 1749900432497 | I21: 107 | K21: THB | L21: IG07 | M21: _SYS00000000092 | N21: _SYS00000000146
A22: =_xlfn.XLOOKUP(I22,Sheet1!B:B,Sheet1!A:A,0) -> 939 | B22: S | C22: 20 | D22: ก-0020 | E22: บริษัท | F22: กัญญา เฮ้าส์ จำกัด | G22: บริษัท กัญญา เฮ้าส์ จำกัด | H22: 105564141261 | I22: 101 | K22: THB | L22: IG07 | M22: _SYS00000000092 | N22: _SYS00000000146 | R22: 0
A23: =_xlfn.XLOOKUP(I23,Sheet1!B:B,Sheet1!A:A,0) -> 985 | B23: S | C23: 21 | D23: ก-0021 | E23: ห้างหุ้นส่วนจำกัด | F23: ก้าวนำ โฆษณา | G23: ห้างหุ้นส่วนจำกัด ก้าวนำ โฆษณา | H23: 213548002976 | I23: 108 | K23: THB | L23: IG07 | M23: _SYS00000000092 | N23: _SYS00000000146 | R23: 0
A24: =_xlfn.XLOOKUP(I24,Sheet1!B:B,Sheet1!A:A,0) -> 939 | B24: S | C24: 22 | D24: ก-0022 | E24: บริษัท | F24: ก้าวหน้า 99 จำกัด | G24: บริษัท ก้าวหน้า 99 จำกัด | H24: 105552128981 | I24: 101 | K24: THB | L24: IG07 | M24: _SYS00000000092 | N24: _SYS00000000146 | R24: 0
A25: =_xlfn.XLOOKUP(I25,Sheet1!B:B,Sheet1!A:A,0) -> 939 | B25: S | C25: 23 | D25: ก-0023 | E25: บริษัท | F25: โกลเด้น ไทม์ พริ้นติ้ง จำกัด | G25: บริษัท โกลเด้น ไทม์ พริ้นติ้ง จำกัด | H25: 105539047655 | I25: 101 | K25: THB | L25: IG07 | M25: _SYS00000000092 | N25: _SYS00000000146 | R25: 0
A26: =_xlfn.XLOOKUP(I26,Sheet1!B:B,Sheet1!A:A,0) -> 939 | B26: S | C26: 24 | D26: ก-0024 | E26: บริษัท | F26: เก็ทเบรด จำกัด | G26: บริษัท เก็ทเบรด จำกัด | H26: 135566024547 | I26: 101 | K26: THB | L26: IG07 | M26: _SYS00000000092 | N26: _SYS00000000146 | R26: 0
A27: =_xlfn.XLOOKUP(I27,Sheet1!B:B,Sheet1!A:A,0) -> 939 | B27: S | C27: 25 | D27: ก-0025 | E27: บริษัท | F27: กันตา 136 (ไทยแลนด์) จำกัด | G27: บริษัท กันตา 136 (ไทยแลนด์) จำกัด | H27: 305564006141 | I27: 101 | K27: THB | L27: IG07 | M27: _SYS00000000092 | N27: _SYS00000000146 | R27: 0
A28: =_xlfn.XLOOKUP(I28,Sheet1!B:B,Sheet1!A:A,0) -> 939 | B28: S | C28: 26 | D28: ค-0001 | E28: บริษัท | F28: โคตรคูล จำกัด | G28: บริษัท โคตรคูล จำกัด | H28: 105560091714 | I28: 101 | K28: THB | L28: IG07 | M28: _SYS00000000092 | N28: _SYS00000000146 | R28: 0
A29: =_xlfn.XLOOKUP(I29,Sheet1!B:B,Sheet1!A:A,0) -> 939 | B29: S | C29: 27 | D29: ค-0002 | E29: บริษัท | F29: ควอนต้าซิสเต็มส์ เอเซียแปซิฟิค จำกัด | G29: บริษัท ควอนต้าซิสเต็มส์ เอเซียแปซิฟิค จำกัด | H29: 105554045919 | I29: 101 | K29: THB | L29: IG07 | M29: _SYS00000000092 | N29: _SYS00000000146 | R29: 0
A30: =_xlfn.XLOOKUP(I30,Sheet1!B:B,Sheet1!A:A,0) -> 939 | B30: S | C30: 28 | D30: ค-0003 | E30: บริษัท | F30: คาณีน ลาปิเน่ แอดวานซ์ จำกัด | G30: บริษัท คาณีน ลาปิเน่ แอดวานซ์ จำกัด | H30: 105560012512 | I30: 101 | K30: THB | L30: IG07 | M30: _SYS00000000092 | N30: _SYS00000000146 | R30: 0
A31: =_xlfn.XLOOKUP(I31,Sheet1!B:B,Sheet1!A:A,0) -> 939 | B31: S | C31: 29 | D31: ค-0004 | E31: บริษัท | F31: เคเค แฮปปี้ จำกัด | G31: บริษัท เคเค แฮปปี้ จำกัด | H31: 105564087011 | I31: 101 | K31: THB | L31: IG07 | M31: _SYS00000000092 | N31: _SYS00000000146 | R31: 0
A32: =_xlfn.XLOOKUP(I32,Sheet1!B:B,Sheet1!A:A,0) -> 939 | B32: S | C32: 30 | D32: ค-0005 | E32: บริษัท | F32: คุณแม่แจ็ค จำกัด | G32: บริษัท คุณแม่แจ็ค จำกัด | H32: 125558023316 | I32: 101 | K32: THB | L32: IG07 | M32: _SYS00000000092 | N32: _SYS00000000146 | R32: 0
A33: =_xlfn.XLOOKUP(I33,Sheet1!B:B,Sheet1!A:A,0) -> 939 | B33: S | C33: 31 | D33: ค-0006 | E33: บริษัท | F33: คอมเซเว่น จำกัด (มหาชน) | G33: บริษัท คอมเซเว่น จำกัด (มหาชน) | H33: 107557000462 | I33: 101 | K33: THB | L33: IG07 | M33: _SYS00000000092 | N33: _SYS00000000146 | R33: 0
... A47: =_xlfn.XLOOKUP(I47,Sheet1!B:B,Sheet1!A:A,0) -> 939 | B47: S | C47: 45 | D47: ค-0020 | E47: บริษัท | F47: คอมมอนเดย์ จำกัด | G47: บริษัท คอมมอนเดย์ จำกัด | H47: 105567090926 | I47: 101 | K47: THB | L47: IG07 | M47: _SYS00000000092 | N47: _SYS00000000146 | R47: 0
A48: =_xlfn.XLOOKUP(I48,Sheet1!B:B,Sheet1!A:A,0) -> 940 | B48: S | C48: 46 | D48: ฆ-0001 | E48: นาย | F48: ฆนพัฒน์ หมื่นจินะ | G48: นาย ฆนพัฒน์ หมื่นจินะ | H48: 1529900485886 | I48: 107 | K48: THB | L48: IG07 | M48: _SYS00000000092 | N48: _SYS00000000146
A49: =_xlfn.XLOOKUP(I49,Sheet1!B:B,Sheet1!A:A,0) -> 939 | B49: S | C49: 47 | D49: ง-0001 | E49: บริษัท | F49: งามวงศ์วานซอปปิ้งมอลล์ จำกัด | G49: บริษัท งามวงศ์วานซอปปิ้งมอลล์ จำกัด | H49: 105532042712 | I49: 101 | K49: THB | L49: IG07 | M49: _SYS00000000092 | N49: _SYS00000000146 | R49: 0
A50: =_xlfn.XLOOKUP(I50,Sheet1!B:B,Sheet1!A:A,0) -> 939 | B50: S | C50: 48 | D50: จ-0001 | E50: บริษัท | F50: เจ อาร์ โกลบอล คอมเมิร์ซ จำกัด | G50: บริษัท เจ อาร์ โกลบอล คอมเมิร์ซ จำกัด | H50: 105560096988 | I50: 101 | J50: 2 | K50: THB | L50: IG07 | M50: _SYS00000000092 | N50: _SYS00000000146 | R50: 0
A51: =_xlfn.XLOOKUP(I51,Sheet1!B:B,Sheet1!A:A,0) -> 939 | B51: S | C51: 49 | D51: จ-0002 | E51: บริษัท | F51: เจ.คิม 2010 จำกัด | G51: บริษัท เจ.คิม 2010 จำกัด | H51: 105552089587 | I51: 101 | K51: THB | L51: IG07 | M51: _SYS00000000092 | N51: _SYS00000000146 | R51: 0
A52: =_xlfn.XLOOKUP(I52,Sheet1!B:B,Sheet1!A:A,0) -> 939 | B52: S | C52: 50 | D52: จ-0003 | E52: บริษัท | F52: เจโฟซี มีเดีย จำกัด | G52: บริษัท เจโฟซี มีเดีย จำกัด | H52: 105564093606 | I52: 101 | K52: THB | L52: IG07 | M52: _SYS00000000092 | N52: _SYS00000000146 | R52: 0
A53: =_xlfn.XLOOKUP(I53,Sheet1!B:B,Sheet1!A:A,0) -> 939 | B53: S | C53: 51 | D53: จ-0004 | E53: บริษัท | F53: เจ.ไอ.บี.คอมพิวเตอร์ กรุ๊ป จำกัด | G53: บริษัท เจ.ไอ.บี.คอมพิวเตอร์ กรุ๊ป จำกัด | H53: 3030522191 | I53: 101 | K53: THB | L53: IG07 | M53: _SYS00000000092 | N53: _SYS00000000146 | R53: 0
...

Sheet Sheet1
A2: series
A3: 939 | B3: 101 | C3: Company
A4: 940 | B4: 107 | C4: Person
A5: 942 | B5: 109 | C5: เจ้าหนี้อื่น
A6: 985 | B6: 108 | C6: หจก.
